{
 "cells": [
  {
   "cell_type": "code",
   "execution_count": null,
   "metadata": {},
   "outputs": [],
   "source": [
    "import cv2\n",
    "import os\n",
    "import numpy as np\n",
    "import tensorflow as tf\n",
    "from tensorflow import keras"
   ]
  },
  {
   "cell_type": "code",
   "execution_count": 2,
   "metadata": {},
   "outputs": [
    {
     "name": "stdout",
     "output_type": "stream",
     "text": [
      "[name: \"/device:CPU:0\"\n",
      "device_type: \"CPU\"\n",
      "memory_limit: 268435456\n",
      "locality {\n",
      "}\n",
      "incarnation: 14086615437682098837\n",
      ", name: \"/device:GPU:0\"\n",
      "device_type: \"GPU\"\n",
      "memory_limit: 5077532672\n",
      "locality {\n",
      "  bus_id: 1\n",
      "  links {\n",
      "  }\n",
      "}\n",
      "incarnation: 17252830673682003682\n",
      "physical_device_desc: \"device: 0, name: NVIDIA GeForce GTX 1060, pci bus id: 0000:01:00.0, compute capability: 6.1\"\n",
      "]\n"
     ]
    }
   ],
   "source": [
    "from tensorflow.python.client import device_lib\n",
    "print(device_lib.list_local_devices())"
   ]
  },
  {
   "cell_type": "code",
   "execution_count": 3,
   "metadata": {},
   "outputs": [],
   "source": [
    "path =\"./model/haarcaschaarcascade_frontalface_default.xml\""
   ]
  },
  {
   "cell_type": "code",
   "execution_count": 4,
   "metadata": {},
   "outputs": [
    {
     "name": "stdout",
     "output_type": "stream",
     "text": [
      "WARNING:tensorflow:Unable to create a python object for variable <tf.Variable 'global_step:0' shape=() dtype=int64_ref> because it is a reference variable. It may not be visible to training APIs. If this is a problem, consider rebuilding the SavedModel after running tf.compat.v1.enable_resource_variables().\n",
      "WARNING:tensorflow:Unable to create a python object for variable <tf.Variable 'layer1/conv2d/kernel:0' shape=(3, 3, 3, 32) dtype=float32_ref> because it is a reference variable. It may not be visible to training APIs. If this is a problem, consider rebuilding the SavedModel after running tf.compat.v1.enable_resource_variables().\n",
      "WARNING:tensorflow:Unable to create a python object for variable <tf.Variable 'layer1/conv2d/bias:0' shape=(32,) dtype=float32_ref> because it is a reference variable. It may not be visible to training APIs. If this is a problem, consider rebuilding the SavedModel after running tf.compat.v1.enable_resource_variables().\n",
      "WARNING:tensorflow:Unable to create a python object for variable <tf.Variable 'layer2/conv2d/kernel:0' shape=(3, 3, 32, 64) dtype=float32_ref> because it is a reference variable. It may not be visible to training APIs. If this is a problem, consider rebuilding the SavedModel after running tf.compat.v1.enable_resource_variables().\n",
      "WARNING:tensorflow:Unable to create a python object for variable <tf.Variable 'layer2/conv2d/bias:0' shape=(64,) dtype=float32_ref> because it is a reference variable. It may not be visible to training APIs. If this is a problem, consider rebuilding the SavedModel after running tf.compat.v1.enable_resource_variables().\n",
      "WARNING:tensorflow:Unable to create a python object for variable <tf.Variable 'global_step:0' shape=() dtype=int64_ref> because it is a reference variable. It may not be visible to training APIs. If this is a problem, consider rebuilding the SavedModel after running tf.compat.v1.enable_resource_variables().\n",
      "WARNING:tensorflow:Unable to create a python object for variable <tf.Variable 'layer1/conv2d/kernel:0' shape=(3, 3, 3, 32) dtype=float32_ref> because it is a reference variable. It may not be visible to training APIs. If this is a problem, consider rebuilding the SavedModel after running tf.compat.v1.enable_resource_variables().\n",
      "WARNING:tensorflow:Unable to create a python object for variable <tf.Variable 'layer1/conv2d/bias:0' shape=(32,) dtype=float32_ref> because it is a reference variable. It may not be visible to training APIs. If this is a problem, consider rebuilding the SavedModel after running tf.compat.v1.enable_resource_variables().\n",
      "WARNING:tensorflow:Unable to create a python object for variable <tf.Variable 'layer2/conv2d/kernel:0' shape=(3, 3, 32, 64) dtype=float32_ref> because it is a reference variable. It may not be visible to training APIs. If this is a problem, consider rebuilding the SavedModel after running tf.compat.v1.enable_resource_variables().\n",
      "WARNING:tensorflow:Unable to create a python object for variable <tf.Variable 'layer2/conv2d/bias:0' shape=(64,) dtype=float32_ref> because it is a reference variable. It may not be visible to training APIs. If this is a problem, consider rebuilding the SavedModel after running tf.compat.v1.enable_resource_variables().\n",
      "WARNING:tensorflow:Unable to create a python object for variable <tf.Variable 'global_step:0' shape=() dtype=int64_ref> because it is a reference variable. It may not be visible to training APIs. If this is a problem, consider rebuilding the SavedModel after running tf.compat.v1.enable_resource_variables().\n",
      "WARNING:tensorflow:Unable to create a python object for variable <tf.Variable 'layer1/conv2d/kernel:0' shape=(3, 3, 3, 32) dtype=float32_ref> because it is a reference variable. It may not be visible to training APIs. If this is a problem, consider rebuilding the SavedModel after running tf.compat.v1.enable_resource_variables().\n",
      "WARNING:tensorflow:Unable to create a python object for variable <tf.Variable 'layer1/conv2d/bias:0' shape=(32,) dtype=float32_ref> because it is a reference variable. It may not be visible to training APIs. If this is a problem, consider rebuilding the SavedModel after running tf.compat.v1.enable_resource_variables().\n",
      "WARNING:tensorflow:Unable to create a python object for variable <tf.Variable 'layer2/conv2d/kernel:0' shape=(3, 3, 32, 64) dtype=float32_ref> because it is a reference variable. It may not be visible to training APIs. If this is a problem, consider rebuilding the SavedModel after running tf.compat.v1.enable_resource_variables().\n",
      "WARNING:tensorflow:Unable to create a python object for variable <tf.Variable 'layer2/conv2d/bias:0' shape=(64,) dtype=float32_ref> because it is a reference variable. It may not be visible to training APIs. If this is a problem, consider rebuilding the SavedModel after running tf.compat.v1.enable_resource_variables().\n",
      "WARNING:tensorflow:Unable to create a python object for variable <tf.Variable 'global_step:0' shape=() dtype=int64_ref> because it is a reference variable. It may not be visible to training APIs. If this is a problem, consider rebuilding the SavedModel after running tf.compat.v1.enable_resource_variables().\n",
      "WARNING:tensorflow:Unable to create a python object for variable <tf.Variable 'layer1/conv2d/kernel:0' shape=(3, 3, 3, 32) dtype=float32_ref> because it is a reference variable. It may not be visible to training APIs. If this is a problem, consider rebuilding the SavedModel after running tf.compat.v1.enable_resource_variables().\n",
      "WARNING:tensorflow:Unable to create a python object for variable <tf.Variable 'layer1/conv2d/bias:0' shape=(32,) dtype=float32_ref> because it is a reference variable. It may not be visible to training APIs. If this is a problem, consider rebuilding the SavedModel after running tf.compat.v1.enable_resource_variables().\n",
      "WARNING:tensorflow:Unable to create a python object for variable <tf.Variable 'layer2/conv2d/kernel:0' shape=(3, 3, 32, 64) dtype=float32_ref> because it is a reference variable. It may not be visible to training APIs. If this is a problem, consider rebuilding the SavedModel after running tf.compat.v1.enable_resource_variables().\n",
      "WARNING:tensorflow:Unable to create a python object for variable <tf.Variable 'layer2/conv2d/bias:0' shape=(64,) dtype=float32_ref> because it is a reference variable. It may not be visible to training APIs. If this is a problem, consider rebuilding the SavedModel after running tf.compat.v1.enable_resource_variables().\n"
     ]
    },
    {
     "ename": "error",
     "evalue": "OpenCV(3.4.2) C:\\projects\\opencv-python\\opencv\\modules\\imgproc\\src\\undistort.cpp:384: error: (-215:Assertion failed) (((_src) != 0 && (((const CvMat*)(_src))->type & 0xFFFF0000) == 0x42420000 && ((const CvMat*)(_src))->cols > 0 && ((const CvMat*)(_src))->rows > 0) && ((const CvMat*)(_src))->data.ptr != 0) && (((_dst) != 0 && (((const CvMat*)(_dst))->type & 0xFFFF0000) == 0x42420000 && ((const CvMat*)(_dst))->cols > 0 && ((const CvMat*)(_dst))->rows > 0) && ((const CvMat*)(_dst))->data.ptr != 0) && (_src->rows == 1 || _src->cols == 1) && (_dst->rows == 1 || _dst->cols == 1) && _src->cols + _src->rows - 1 == _dst->rows + _dst->cols - 1 && (((_src->type) & ((1 << 3)*512 - 1)) == (((5) & ((1 << 3) - 1)) + (((2)-1) << 3)) || ((_src->type) & ((1 << 3)*512 - 1)) == (((6) & ((1 << 3) - 1)) + (((2)-1) << 3))) && (((_dst->type) & ((1 << 3)*512 - 1)) == (((5) & ((1 << 3) - 1)) + (((2)-1) << 3)) || ((_dst->type) & ((1 << 3)*512 - 1)) == (((6) & ((1 << 3) - 1)) + (((2)-1) << 3))) in function 'cvUndistortPointsInternal'\n",
     "output_type": "error",
     "traceback": [
      "\u001b[1;31m---------------------------------------------------------------------------\u001b[0m",
      "\u001b[1;31merror\u001b[0m                                     Traceback (most recent call last)",
      "\u001b[1;32m<ipython-input-4-c6db7f7638c6>\u001b[0m in \u001b[0;36m<module>\u001b[1;34m\u001b[0m\n\u001b[0;32m    258\u001b[0m                                 ], dtype=\"double\")\n\u001b[0;32m    259\u001b[0m             \u001b[0mdist_coeffs\u001b[0m \u001b[1;33m=\u001b[0m \u001b[0mnp\u001b[0m\u001b[1;33m.\u001b[0m\u001b[0mzeros\u001b[0m\u001b[1;33m(\u001b[0m\u001b[1;33m(\u001b[0m\u001b[1;36m4\u001b[0m\u001b[1;33m,\u001b[0m\u001b[1;36m1\u001b[0m\u001b[1;33m)\u001b[0m\u001b[1;33m)\u001b[0m \u001b[1;31m# Assuming no lens distortion\u001b[0m\u001b[1;33m\u001b[0m\u001b[1;33m\u001b[0m\u001b[0m\n\u001b[1;32m--> 260\u001b[1;33m             \u001b[1;33m(\u001b[0m\u001b[0msuccess\u001b[0m\u001b[1;33m,\u001b[0m \u001b[0mrotation_vector\u001b[0m\u001b[1;33m,\u001b[0m \u001b[0mtranslation_vector\u001b[0m\u001b[1;33m)\u001b[0m \u001b[1;33m=\u001b[0m \u001b[0mcv2\u001b[0m\u001b[1;33m.\u001b[0m\u001b[0msolvePnP\u001b[0m\u001b[1;33m(\u001b[0m\u001b[0mmodel_points\u001b[0m\u001b[1;33m,\u001b[0m \u001b[0mimage_points\u001b[0m\u001b[1;33m,\u001b[0m \u001b[0mcamera_matrix\u001b[0m\u001b[1;33m,\u001b[0m \u001b[0mdist_coeffs\u001b[0m\u001b[1;33m,\u001b[0m \u001b[0mflags\u001b[0m\u001b[1;33m=\u001b[0m\u001b[0mcv2\u001b[0m\u001b[1;33m.\u001b[0m\u001b[0mSOLVEPNP_UPNP\u001b[0m\u001b[1;33m)\u001b[0m\u001b[1;33m\u001b[0m\u001b[1;33m\u001b[0m\u001b[0m\n\u001b[0m\u001b[0;32m    261\u001b[0m \u001b[1;33m\u001b[0m\u001b[0m\n\u001b[0;32m    262\u001b[0m \u001b[1;33m\u001b[0m\u001b[0m\n",
      "\u001b[1;31merror\u001b[0m: OpenCV(3.4.2) C:\\projects\\opencv-python\\opencv\\modules\\imgproc\\src\\undistort.cpp:384: error: (-215:Assertion failed) (((_src) != 0 && (((const CvMat*)(_src))->type & 0xFFFF0000) == 0x42420000 && ((const CvMat*)(_src))->cols > 0 && ((const CvMat*)(_src))->rows > 0) && ((const CvMat*)(_src))->data.ptr != 0) && (((_dst) != 0 && (((const CvMat*)(_dst))->type & 0xFFFF0000) == 0x42420000 && ((const CvMat*)(_dst))->cols > 0 && ((const CvMat*)(_dst))->rows > 0) && ((const CvMat*)(_dst))->data.ptr != 0) && (_src->rows == 1 || _src->cols == 1) && (_dst->rows == 1 || _dst->cols == 1) && _src->cols + _src->rows - 1 == _dst->rows + _dst->cols - 1 && (((_src->type) & ((1 << 3)*512 - 1)) == (((5) & ((1 << 3) - 1)) + (((2)-1) << 3)) || ((_src->type) & ((1 << 3)*512 - 1)) == (((6) & ((1 << 3) - 1)) + (((2)-1) << 3))) && (((_dst->type) & ((1 << 3)*512 - 1)) == (((5) & ((1 << 3) - 1)) + (((2)-1) << 3)) || ((_dst->type) & ((1 << 3)*512 - 1)) == (((6) & ((1 << 3) - 1)) + (((2)-1) << 3))) in function 'cvUndistortPointsInternal'\n"
     ]
    }
   ],
   "source": [
    "\"\"\"Human facial landmark detector based on Convolutional Neural Network.\"\"\"\n",
    "import cv2\n",
    "import numpy as np\n",
    "import tensorflow as tf\n",
    "from tensorflow import keras\n",
    "import math\n",
    "\n",
    "class FaceDetector:\n",
    "    \"\"\"Detect human face from image\"\"\"\n",
    "\n",
    "    def __init__(self, dnn_proto_text='models/deploy.prototxt',\n",
    "                 dnn_model='models/res10_300x300_ssd_iter_140000.caffemodel'):\n",
    "        self.face_net = cv2.dnn.readNetFromCaffe(dnn_proto_text, dnn_model)\n",
    "        self.detection_result = None\n",
    "\n",
    "    def get_faceboxes(self, image, threshold=0.5):\n",
    "        \"\"\"\n",
    "        Get the bounding box of faces in image using dnn.\n",
    "        \"\"\"\n",
    "        rows, cols, _ = image.shape\n",
    "\n",
    "        confidences = []\n",
    "        faceboxes = []\n",
    "\n",
    "        self.face_net.setInput(cv2.dnn.blobFromImage(\n",
    "            image, 1.0, (300, 300), (104.0, 177.0, 123.0), False, False))\n",
    "        detections = self.face_net.forward()\n",
    "\n",
    "        for result in detections[0, 0, :, :]:\n",
    "            confidence = result[2]\n",
    "            if confidence > threshold:\n",
    "                x_left_bottom = int(result[3] * cols)\n",
    "                y_left_bottom = int(result[4] * rows)\n",
    "                x_right_top = int(result[5] * cols)\n",
    "                y_right_top = int(result[6] * rows)\n",
    "                confidences.append(confidence)\n",
    "                faceboxes.append(\n",
    "                    [x_left_bottom, y_left_bottom, x_right_top, y_right_top])\n",
    "\n",
    "        self.detection_result = [faceboxes, confidences]\n",
    "\n",
    "        return confidences, faceboxes\n",
    "\n",
    "    def draw_all_result(self, image):\n",
    "        \"\"\"Draw the detection result on image\"\"\"\n",
    "        for facebox, conf in self.detection_result:\n",
    "            cv2.rectangle(image, (facebox[0], facebox[1]),\n",
    "                          (facebox[2], facebox[3]), (0, 255, 0))\n",
    "            label = \"face: %.4f\" % conf\n",
    "            label_size, base_line = cv2.getTextSize(\n",
    "                label, cv2.FONT_HERSHEY_SIMPLEX, 0.5, 1)\n",
    "\n",
    "            cv2.rectangle(image, (facebox[0], facebox[1] - label_size[1]),\n",
    "                          (facebox[0] + label_size[0],\n",
    "                           facebox[1] + base_line),\n",
    "                          (0, 255, 0), cv2.FILLED)\n",
    "            cv2.putText(image, label, (facebox[0], facebox[1]),\n",
    "                        cv2.FONT_HERSHEY_SIMPLEX, 0.5, (0, 0, 0))\n",
    "\n",
    "\n",
    "class MarkDetector:\n",
    "    def __init__(self, saved_model='models/pose_model'):\n",
    "        \"\"\"Initialization\"\"\"\n",
    "        # A face detector is required for mark detection.\n",
    "        self.face_detector = FaceDetector()\n",
    "\n",
    "        self.cnn_input_size = 128\n",
    "        self.marks = None\n",
    "\n",
    "        # Restore model from the saved_model file.\n",
    "        self.model = keras.models.load_model(saved_model)\n",
    "\n",
    "    @staticmethod\n",
    "    def draw_box(image, boxes, box_color=(255, 255, 255)):\n",
    "        \"\"\"Draw square boxes on image\"\"\"\n",
    "        for box in boxes:\n",
    "            cv2.rectangle(image,\n",
    "                          (box[0], box[1]),\n",
    "                          (box[2], box[3]), box_color, 3)\n",
    "\n",
    "    @staticmethod\n",
    "    def move_box(box, offset):\n",
    "        \"\"\"Move the box to direction specified by vector offset\"\"\"\n",
    "        left_x = box[0] + offset[0]\n",
    "        top_y = box[1] + offset[1]\n",
    "        right_x = box[2] + offset[0]\n",
    "        bottom_y = box[3] + offset[1]\n",
    "        return [left_x, top_y, right_x, bottom_y]\n",
    "\n",
    "    @staticmethod\n",
    "    def get_square_box(box):\n",
    "        \"\"\"Get a square box out of the given box, by expanding it.\"\"\"\n",
    "        left_x = box[0]\n",
    "        top_y = box[1]\n",
    "        right_x = box[2]\n",
    "        bottom_y = box[3]\n",
    "\n",
    "        box_width = right_x - left_x\n",
    "        box_height = bottom_y - top_y\n",
    "\n",
    "        # Check if box is already a square. If not, make it a square.\n",
    "        diff = box_height - box_width\n",
    "        delta = int(abs(diff) / 2)\n",
    "\n",
    "        if diff == 0:                   # Already a square.\n",
    "            return box\n",
    "        elif diff > 0:                  # Height > width, a slim box.\n",
    "            left_x -= delta\n",
    "            right_x += delta\n",
    "            if diff % 2 == 1:\n",
    "                right_x += 1\n",
    "        else:                           # Width > height, a short box.\n",
    "            top_y -= delta\n",
    "            bottom_y += delta\n",
    "            if diff % 2 == 1:\n",
    "                bottom_y += 1\n",
    "\n",
    "        # Make sure box is always square.\n",
    "        assert ((right_x - left_x) == (bottom_y - top_y)), 'Box is not square.'\n",
    "\n",
    "        return [left_x, top_y, right_x, bottom_y]\n",
    "\n",
    "    @staticmethod\n",
    "    def box_in_image(box, image):\n",
    "        \"\"\"Check if the box is in image\"\"\"\n",
    "        rows = image.shape[0]\n",
    "        cols = image.shape[1]\n",
    "        return box[0] >= 0 and box[1] >= 0 and box[2] <= cols and box[3] <= rows\n",
    "\n",
    "    def extract_cnn_facebox(self, image):\n",
    "        \"\"\"Extract face area from image.\"\"\"\n",
    "        _, raw_boxes = self.face_detector.get_faceboxes(\n",
    "            image=image, threshold=0.5)\n",
    "        a = []\n",
    "        for box in raw_boxes:\n",
    "            # Move box down.\n",
    "            # diff_height_width = (box[3] - box[1]) - (box[2] - box[0])\n",
    "            offset_y = int(abs((box[3] - box[1]) * 0.1))\n",
    "            box_moved = self.move_box(box, [0, offset_y])\n",
    "\n",
    "            # Make box square.\n",
    "            facebox = self.get_square_box(box_moved)\n",
    "\n",
    "            if self.box_in_image(facebox, image):\n",
    "                a.append(facebox)\n",
    "\n",
    "        return a\n",
    "\n",
    "    def detect_marks(self, image_np):\n",
    "        \"\"\"Detect marks from image\"\"\"\n",
    "\n",
    "        # # Actual detection.\n",
    "        predictions = self.model.signatures[\"predict\"](\n",
    "            tf.constant(image_np, dtype=tf.uint8))\n",
    "\n",
    "        # Convert predictions to landmarks.\n",
    "        marks = np.array(predictions['output']).flatten()[:136]\n",
    "        marks = np.reshape(marks, (-1, 2))\n",
    "\n",
    "        return marks\n",
    "\n",
    "    @staticmethod\n",
    "    def draw_marks(image, marks, color=(255, 255, 255)):\n",
    "        \"\"\"Draw mark points on image\"\"\"\n",
    "        for mark in marks:\n",
    "            cv2.circle(image, (int(mark[0]), int(\n",
    "                mark[1])), 2, color, -1, cv2.LINE_AA)\n",
    "            \n",
    "            \n",
    "def draw_annotation_box(img, rotation_vector, translation_vector, camera_matrix, color=(255, 255, 0), line_width=2):\n",
    "    \"\"\"Draw a 3D box as annotation of pose\"\"\"\n",
    "    point_3d = []\n",
    "    dist_coeffs = np.zeros((4,1))\n",
    "    rear_size = 1\n",
    "    rear_depth = 0\n",
    "    point_3d.append((-rear_size, -rear_size, rear_depth))\n",
    "    point_3d.append((-rear_size, rear_size, rear_depth))\n",
    "    point_3d.append((rear_size, rear_size, rear_depth))\n",
    "    point_3d.append((rear_size, -rear_size, rear_depth))\n",
    "    point_3d.append((-rear_size, -rear_size, rear_depth))\n",
    "\n",
    "    front_size = img.shape[1]\n",
    "    front_depth = front_size*2\n",
    "    point_3d.append((-front_size, -front_size, front_depth))\n",
    "    point_3d.append((-front_size, front_size, front_depth))\n",
    "    point_3d.append((front_size, front_size, front_depth))\n",
    "    point_3d.append((front_size, -front_size, front_depth))\n",
    "    point_3d.append((-front_size, -front_size, front_depth))\n",
    "    point_3d = np.array(point_3d, dtype=np.float).reshape(-1, 3)\n",
    "\n",
    "    # Map to 2d img points\n",
    "    (point_2d, _) = cv2.projectPoints(point_3d,\n",
    "                                      rotation_vector,\n",
    "                                      translation_vector,\n",
    "                                      camera_matrix,\n",
    "                                      dist_coeffs)\n",
    "    point_2d = np.int32(point_2d.reshape(-1, 2))\n",
    "    \n",
    "\n",
    "    # # Draw all the lines\n",
    "    # cv2.polylines(img, [point_2d], True, color, line_width, cv2.LINE_AA)\n",
    "    k = (point_2d[5] + point_2d[8])//2\n",
    "    # cv2.line(img, tuple(point_2d[1]), tuple(\n",
    "    #     point_2d[6]), color, line_width, cv2.LINE_AA)\n",
    "    # cv2.line(img, tuple(point_2d[2]), tuple(\n",
    "    #     point_2d[7]), color, line_width, cv2.LINE_AA)\n",
    "    # cv2.line(img, tuple(point_2d[3]), tuple(\n",
    "    #     point_2d[8]), color, line_width, cv2.LINE_AA)\n",
    "    \n",
    "    return(point_2d[2], k)\n",
    "    \n",
    "mark_detector = MarkDetector()\n",
    "cap = cv2.VideoCapture(0)\n",
    "ret, img = cap.read()\n",
    "size = img.shape\n",
    "font = cv2.FONT_HERSHEY_SIMPLEX \n",
    "# 3D model points.\n",
    "model_points = np.array([\n",
    "                            (0.0, 0.0, 0.0),             # Nose tip\n",
    "                            (0.0, -330.0, -65.0),        # Chin\n",
    "                            (-225.0, 170.0, -135.0),     # Left eye left corner\n",
    "                            (225.0, 170.0, -135.0),      # Right eye right corne\n",
    "                            (-150.0, -150.0, -125.0),    # Left Mouth corner\n",
    "                            (150.0, -150.0, -125.0)      # Right mouth corner\n",
    "                        ])\n",
    "\n",
    "# Camera internals\n",
    "focal_length = size[1]\n",
    "center = (size[1]/2, size[0]/2)\n",
    "camera_matrix = np.array(\n",
    "                         [[focal_length, 0, center[0]],\n",
    "                         [0, focal_length, center[1]],\n",
    "                         [0, 0, 1]], dtype = \"double\"\n",
    "                         )\n",
    "while True:\n",
    "    ret, img = cap.read()\n",
    "    if ret == True:\n",
    "        faceboxes = mark_detector.extract_cnn_facebox(img)\n",
    "        for facebox in faceboxes:\n",
    "            face_img = img[facebox[1]: facebox[3],\n",
    "                     facebox[0]: facebox[2]]\n",
    "            face_img = cv2.resize(face_img, (128, 128))\n",
    "            face_img = cv2.cvtColor(face_img, cv2.COLOR_BGR2RGB)\n",
    "            marks = mark_detector.detect_marks([face_img])\n",
    "            marks *= (facebox[2] - facebox[0])\n",
    "            marks[:, 0] += facebox[0]\n",
    "            marks[:, 1] += facebox[1]\n",
    "            shape = marks.astype(np.uint)\n",
    "            # mark_detector.draw_marks(img, marks, color=(0, 255, 0))\n",
    "            image_points = np.array([\n",
    "                                    shape[30],     # Nose tip\n",
    "                                    shape[8],     # Chin\n",
    "                                    shape[36],     # Left eye left corner\n",
    "                                    shape[45],     # Right eye right corne\n",
    "                                    shape[48],     # Left Mouth corner\n",
    "                                    shape[54]      # Right mouth corner\n",
    "                                ], dtype=\"double\")\n",
    "            dist_coeffs = np.zeros((4,1)) # Assuming no lens distortion\n",
    "            (success, rotation_vector, translation_vector) = cv2.solvePnP(model_points, image_points, camera_matrix, dist_coeffs, flags=cv2.SOLVEPNP_UPNP)\n",
    "            \n",
    "            \n",
    "            # Project a 3D point (0, 0, 1000.0) onto the image plane.\n",
    "            # We use this to draw a line sticking out of the nose\n",
    "            \n",
    "            (nose_end_point2D, jacobian) = cv2.projectPoints(np.array([(0.0, 0.0, 1000.0)]), rotation_vector, translation_vector, camera_matrix, dist_coeffs)\n",
    "            \n",
    "            for p in image_points:\n",
    "                cv2.circle(img, (int(p[0]), int(p[1])), 3, (0,0,255), -1)\n",
    "            \n",
    "            \n",
    "            p1 = ( int(image_points[0][0]), int(image_points[0][1]))\n",
    "            p2 = ( int(nose_end_point2D[0][0][0]), int(nose_end_point2D[0][0][1]))\n",
    "            x1, x2 = draw_annotation_box(img, rotation_vector, translation_vector, camera_matrix)\n",
    "\n",
    "            cv2.line(img, p1, p2, (0, 255, 255), 2)\n",
    "            cv2.line(img, tuple(x1), tuple(x2), (255, 255, 0), 2)\n",
    "            # for (x, y) in shape:\n",
    "            #     cv2.circle(img, (x, y), 4, (255, 255, 0), -1)\n",
    "            # cv2.putText(img, str(p1), p1, font, 1, (0, 255, 255), 1)\n",
    "            try:\n",
    "                m = (p2[1] - p1[1])/(p2[0] - p1[0])\n",
    "                ang1 = int(math.degrees(math.atan(m)))\n",
    "            except:\n",
    "                ang1 = 90\n",
    "                \n",
    "            try:\n",
    "                m = (x2[1] - x1[1])/(x2[0] - x1[0])\n",
    "                ang2 = int(math.degrees(math.atan(-1/m)))\n",
    "            except:\n",
    "                ang2 = 90\n",
    "                \n",
    "                # print('div by zero error')\n",
    "            cv2.putText(img, str(ang1), tuple(p1), font, 2, (128, 255, 255), 3)\n",
    "            cv2.putText(img, str(ang2), tuple(x1), font, 2, (255, 255, 128), 3)\n",
    "        cv2.imshow('img', img)\n",
    "        if cv2.waitKey(1) & 0xFF == ord('q'):\n",
    "            break\n",
    "    else:\n",
    "        break\n",
    "cv2.destroyAllWindows()\n",
    "cap.release()"
   ]
  },
  {
   "cell_type": "code",
   "execution_count": null,
   "metadata": {},
   "outputs": [
    {
     "name": "stdout",
     "output_type": "stream",
     "text": [
      "ERROR! Session/line number was not unique in database. History logging moved to new session 2300\n"
     ]
    },
    {
     "name": "stderr",
     "output_type": "stream",
     "text": [
      "ERROR:root:Internal Python error in the inspect module.\n",
      "Below is the traceback from this internal error.\n",
      "\n",
      "ERROR:root:Internal Python error in the inspect module.\n",
      "Below is the traceback from this internal error.\n",
      "\n",
      "ERROR:root:Internal Python error in the inspect module.\n",
      "Below is the traceback from this internal error.\n",
      "\n"
     ]
    },
    {
     "name": "stdout",
     "output_type": "stream",
     "text": [
      "Traceback (most recent call last):\n",
      "  File \"C:\\Users\\acer\\Anaconda3\\envs\\embvr\\lib\\site-packages\\IPython\\core\\interactiveshell.py\", line 3417, in run_code\n",
      "    exec(code_obj, self.user_global_ns, self.user_ns)\n",
      "  File \"<ipython-input-4-ba65f362b3df>\", line 15, in <module>\n",
      "    flags = cv2.CASCADE_SCALE_IMAGE)\n",
      "cv2.error: OpenCV(3.4.2) C:\\projects\\opencv-python\\opencv\\modules\\objdetect\\src\\cascadedetect.cpp:1698: error: (-215:Assertion failed) !empty() in function 'cv::CascadeClassifier::detectMultiScale'\n",
      "\n",
      "\n",
      "During handling of the above exception, another exception occurred:\n",
      "\n",
      "Traceback (most recent call last):\n",
      "  File \"C:\\Users\\acer\\Anaconda3\\envs\\embvr\\lib\\site-packages\\IPython\\core\\interactiveshell.py\", line 2044, in showtraceback\n",
      "    stb = value._render_traceback_()\n",
      "AttributeError: 'error' object has no attribute '_render_traceback_'\n",
      "\n",
      "During handling of the above exception, another exception occurred:\n",
      "\n",
      "Traceback (most recent call last):\n",
      "  File \"C:\\Users\\acer\\Anaconda3\\envs\\embvr\\lib\\site-packages\\IPython\\core\\ultratb.py\", line 1169, in get_records\n",
      "    return _fixed_getinnerframes(etb, number_of_lines_of_context, tb_offset)\n",
      "  File \"C:\\Users\\acer\\Anaconda3\\envs\\embvr\\lib\\site-packages\\IPython\\core\\ultratb.py\", line 316, in wrapped\n",
      "    return f(*args, **kwargs)\n",
      "  File \"C:\\Users\\acer\\Anaconda3\\envs\\embvr\\lib\\site-packages\\IPython\\core\\ultratb.py\", line 350, in _fixed_getinnerframes\n",
      "    records = fix_frame_records_filenames(inspect.getinnerframes(etb, context))\n",
      "  File \"C:\\Users\\acer\\Anaconda3\\envs\\embvr\\lib\\inspect.py\", line 1500, in getinnerframes\n",
      "    frameinfo = (tb.tb_frame,) + getframeinfo(tb, context)\n",
      "  File \"C:\\Users\\acer\\Anaconda3\\envs\\embvr\\lib\\inspect.py\", line 1458, in getframeinfo\n",
      "    filename = getsourcefile(frame) or getfile(frame)\n",
      "  File \"C:\\Users\\acer\\Anaconda3\\envs\\embvr\\lib\\inspect.py\", line 696, in getsourcefile\n",
      "    if getattr(getmodule(object, filename), '__loader__', None) is not None:\n",
      "  File \"C:\\Users\\acer\\Anaconda3\\envs\\embvr\\lib\\inspect.py\", line 733, in getmodule\n",
      "    if ismodule(module) and hasattr(module, '__file__'):\n",
      "  File \"C:\\Users\\acer\\Anaconda3\\envs\\embvr\\lib\\site-packages\\tensorflow\\__init__.py\", line 50, in __getattr__\n",
      "    module = self._load()\n",
      "  File \"C:\\Users\\acer\\Anaconda3\\envs\\embvr\\lib\\site-packages\\tensorflow\\__init__.py\", line 44, in _load\n",
      "    module = _importlib.import_module(self.__name__)\n",
      "  File \"C:\\Users\\acer\\Anaconda3\\envs\\embvr\\lib\\importlib\\__init__.py\", line 127, in import_module\n",
      "    return _bootstrap._gcd_import(name[level:], package, level)\n",
      "  File \"<frozen importlib._bootstrap>\", line 1006, in _gcd_import\n",
      "  File \"<frozen importlib._bootstrap>\", line 983, in _find_and_load\n",
      "  File \"<frozen importlib._bootstrap>\", line 965, in _find_and_load_unlocked\n",
      "ModuleNotFoundError: No module named 'tensorflow_core.estimator'\n",
      "Traceback (most recent call last):\n",
      "  File \"C:\\Users\\acer\\Anaconda3\\envs\\embvr\\lib\\site-packages\\IPython\\core\\interactiveshell.py\", line 3417, in run_code\n",
      "    exec(code_obj, self.user_global_ns, self.user_ns)\n",
      "  File \"<ipython-input-4-ba65f362b3df>\", line 15, in <module>\n",
      "    flags = cv2.CASCADE_SCALE_IMAGE)\n",
      "cv2.error: OpenCV(3.4.2) C:\\projects\\opencv-python\\opencv\\modules\\objdetect\\src\\cascadedetect.cpp:1698: error: (-215:Assertion failed) !empty() in function 'cv::CascadeClassifier::detectMultiScale'\n",
      "\n",
      "\n",
      "During handling of the above exception, another exception occurred:\n",
      "\n",
      "Traceback (most recent call last):\n",
      "  File \"C:\\Users\\acer\\Anaconda3\\envs\\embvr\\lib\\site-packages\\IPython\\core\\interactiveshell.py\", line 2044, in showtraceback\n",
      "    stb = value._render_traceback_()\n",
      "AttributeError: 'error' object has no attribute '_render_traceback_'\n",
      "\n",
      "During handling of the above exception, another exception occurred:\n",
      "\n",
      "Traceback (most recent call last):\n",
      "  File \"C:\\Users\\acer\\Anaconda3\\envs\\embvr\\lib\\site-packages\\IPython\\core\\interactiveshell.py\", line 3337, in run_ast_nodes\n",
      "    if (await self.run_code(code, result,  async_=asy)):\n",
      "  File \"C:\\Users\\acer\\Anaconda3\\envs\\embvr\\lib\\site-packages\\IPython\\core\\interactiveshell.py\", line 3434, in run_code\n",
      "    self.showtraceback(running_compiled_code=True)\n",
      "  File \"C:\\Users\\acer\\Anaconda3\\envs\\embvr\\lib\\site-packages\\IPython\\core\\interactiveshell.py\", line 2047, in showtraceback\n",
      "    value, tb, tb_offset=tb_offset)\n",
      "  File \"C:\\Users\\acer\\Anaconda3\\envs\\embvr\\lib\\site-packages\\IPython\\core\\ultratb.py\", line 1436, in structured_traceback\n",
      "    self, etype, value, tb, tb_offset, number_of_lines_of_context)\n",
      "  File \"C:\\Users\\acer\\Anaconda3\\envs\\embvr\\lib\\site-packages\\IPython\\core\\ultratb.py\", line 1336, in structured_traceback\n",
      "    self, etype, value, tb, tb_offset, number_of_lines_of_context\n",
      "  File \"C:\\Users\\acer\\Anaconda3\\envs\\embvr\\lib\\site-packages\\IPython\\core\\ultratb.py\", line 1193, in structured_traceback\n",
      "    tb_offset)\n",
      "  File \"C:\\Users\\acer\\Anaconda3\\envs\\embvr\\lib\\site-packages\\IPython\\core\\ultratb.py\", line 1150, in format_exception_as_a_whole\n",
      "    last_unique, recursion_repeat = find_recursion(orig_etype, evalue, records)\n",
      "  File \"C:\\Users\\acer\\Anaconda3\\envs\\embvr\\lib\\site-packages\\IPython\\core\\ultratb.py\", line 451, in find_recursion\n",
      "    return len(records), 0\n",
      "TypeError: object of type 'NoneType' has no len()\n",
      "\n",
      "During handling of the above exception, another exception occurred:\n",
      "\n",
      "Traceback (most recent call last):\n",
      "  File \"C:\\Users\\acer\\Anaconda3\\envs\\embvr\\lib\\site-packages\\IPython\\core\\interactiveshell.py\", line 2044, in showtraceback\n",
      "    stb = value._render_traceback_()\n",
      "AttributeError: 'TypeError' object has no attribute '_render_traceback_'\n",
      "\n",
      "During handling of the above exception, another exception occurred:\n",
      "\n",
      "Traceback (most recent call last):\n",
      "  File \"C:\\Users\\acer\\Anaconda3\\envs\\embvr\\lib\\site-packages\\IPython\\core\\ultratb.py\", line 1169, in get_records\n",
      "    return _fixed_getinnerframes(etb, number_of_lines_of_context, tb_offset)\n",
      "  File \"C:\\Users\\acer\\Anaconda3\\envs\\embvr\\lib\\site-packages\\IPython\\core\\ultratb.py\", line 316, in wrapped\n",
      "    return f(*args, **kwargs)\n",
      "  File \"C:\\Users\\acer\\Anaconda3\\envs\\embvr\\lib\\site-packages\\IPython\\core\\ultratb.py\", line 350, in _fixed_getinnerframes\n",
      "    records = fix_frame_records_filenames(inspect.getinnerframes(etb, context))\n",
      "  File \"C:\\Users\\acer\\Anaconda3\\envs\\embvr\\lib\\inspect.py\", line 1500, in getinnerframes\n",
      "    frameinfo = (tb.tb_frame,) + getframeinfo(tb, context)\n",
      "  File \"C:\\Users\\acer\\Anaconda3\\envs\\embvr\\lib\\inspect.py\", line 1458, in getframeinfo\n",
      "    filename = getsourcefile(frame) or getfile(frame)\n",
      "  File \"C:\\Users\\acer\\Anaconda3\\envs\\embvr\\lib\\inspect.py\", line 696, in getsourcefile\n",
      "    if getattr(getmodule(object, filename), '__loader__', None) is not None:\n",
      "  File \"C:\\Users\\acer\\Anaconda3\\envs\\embvr\\lib\\inspect.py\", line 733, in getmodule\n",
      "    if ismodule(module) and hasattr(module, '__file__'):\n",
      "  File \"C:\\Users\\acer\\Anaconda3\\envs\\embvr\\lib\\site-packages\\tensorflow\\__init__.py\", line 50, in __getattr__\n",
      "    module = self._load()\n",
      "  File \"C:\\Users\\acer\\Anaconda3\\envs\\embvr\\lib\\site-packages\\tensorflow\\__init__.py\", line 44, in _load\n",
      "    module = _importlib.import_module(self.__name__)\n",
      "  File \"C:\\Users\\acer\\Anaconda3\\envs\\embvr\\lib\\importlib\\__init__.py\", line 127, in import_module\n",
      "    return _bootstrap._gcd_import(name[level:], package, level)\n",
      "  File \"<frozen importlib._bootstrap>\", line 1006, in _gcd_import\n",
      "  File \"<frozen importlib._bootstrap>\", line 983, in _find_and_load\n",
      "  File \"<frozen importlib._bootstrap>\", line 965, in _find_and_load_unlocked\n",
      "ModuleNotFoundError: No module named 'tensorflow_core.estimator'\n",
      "Traceback (most recent call last):\n",
      "  File \"C:\\Users\\acer\\Anaconda3\\envs\\embvr\\lib\\site-packages\\IPython\\core\\interactiveshell.py\", line 3417, in run_code\n",
      "    exec(code_obj, self.user_global_ns, self.user_ns)\n",
      "  File \"<ipython-input-4-ba65f362b3df>\", line 15, in <module>\n",
      "    flags = cv2.CASCADE_SCALE_IMAGE)\n",
      "cv2.error: OpenCV(3.4.2) C:\\projects\\opencv-python\\opencv\\modules\\objdetect\\src\\cascadedetect.cpp:1698: error: (-215:Assertion failed) !empty() in function 'cv::CascadeClassifier::detectMultiScale'\n",
      "\n",
      "\n",
      "During handling of the above exception, another exception occurred:\n",
      "\n",
      "Traceback (most recent call last):\n",
      "  File \"C:\\Users\\acer\\Anaconda3\\envs\\embvr\\lib\\site-packages\\IPython\\core\\interactiveshell.py\", line 2044, in showtraceback\n",
      "    stb = value._render_traceback_()\n",
      "AttributeError: 'error' object has no attribute '_render_traceback_'\n",
      "\n",
      "During handling of the above exception, another exception occurred:\n",
      "\n",
      "Traceback (most recent call last):\n",
      "  File \"C:\\Users\\acer\\Anaconda3\\envs\\embvr\\lib\\site-packages\\IPython\\core\\interactiveshell.py\", line 3337, in run_ast_nodes\n",
      "    if (await self.run_code(code, result,  async_=asy)):\n",
      "  File \"C:\\Users\\acer\\Anaconda3\\envs\\embvr\\lib\\site-packages\\IPython\\core\\interactiveshell.py\", line 3434, in run_code\n",
      "    self.showtraceback(running_compiled_code=True)\n",
      "  File \"C:\\Users\\acer\\Anaconda3\\envs\\embvr\\lib\\site-packages\\IPython\\core\\interactiveshell.py\", line 2047, in showtraceback\n",
      "    value, tb, tb_offset=tb_offset)\n",
      "  File \"C:\\Users\\acer\\Anaconda3\\envs\\embvr\\lib\\site-packages\\IPython\\core\\ultratb.py\", line 1436, in structured_traceback\n",
      "    self, etype, value, tb, tb_offset, number_of_lines_of_context)\n",
      "  File \"C:\\Users\\acer\\Anaconda3\\envs\\embvr\\lib\\site-packages\\IPython\\core\\ultratb.py\", line 1336, in structured_traceback\n",
      "    self, etype, value, tb, tb_offset, number_of_lines_of_context\n",
      "  File \"C:\\Users\\acer\\Anaconda3\\envs\\embvr\\lib\\site-packages\\IPython\\core\\ultratb.py\", line 1193, in structured_traceback\n",
      "    tb_offset)\n",
      "  File \"C:\\Users\\acer\\Anaconda3\\envs\\embvr\\lib\\site-packages\\IPython\\core\\ultratb.py\", line 1150, in format_exception_as_a_whole\n",
      "    last_unique, recursion_repeat = find_recursion(orig_etype, evalue, records)\n",
      "  File \"C:\\Users\\acer\\Anaconda3\\envs\\embvr\\lib\\site-packages\\IPython\\core\\ultratb.py\", line 451, in find_recursion\n",
      "    return len(records), 0\n",
      "TypeError: object of type 'NoneType' has no len()\n",
      "\n",
      "During handling of the above exception, another exception occurred:\n",
      "\n",
      "Traceback (most recent call last):\n",
      "  File \"C:\\Users\\acer\\Anaconda3\\envs\\embvr\\lib\\site-packages\\IPython\\core\\interactiveshell.py\", line 2044, in showtraceback\n",
      "    stb = value._render_traceback_()\n",
      "AttributeError: 'TypeError' object has no attribute '_render_traceback_'\n",
      "\n",
      "During handling of the above exception, another exception occurred:\n",
      "\n",
      "Traceback (most recent call last):\n",
      "  File \"C:\\Users\\acer\\Anaconda3\\envs\\embvr\\lib\\site-packages\\IPython\\core\\interactiveshell.py\", line 2922, in _run_cell\n",
      "    return runner(coro)\n",
      "  File \"C:\\Users\\acer\\Anaconda3\\envs\\embvr\\lib\\site-packages\\IPython\\core\\async_helpers.py\", line 68, in _pseudo_sync_runner\n",
      "    coro.send(None)\n",
      "  File \"C:\\Users\\acer\\Anaconda3\\envs\\embvr\\lib\\site-packages\\IPython\\core\\interactiveshell.py\", line 3146, in run_cell_async\n",
      "    interactivity=interactivity, compiler=compiler, result=result)\n",
      "  File \"C:\\Users\\acer\\Anaconda3\\envs\\embvr\\lib\\site-packages\\IPython\\core\\interactiveshell.py\", line 3356, in run_ast_nodes\n",
      "    self.showtraceback()\n",
      "  File \"C:\\Users\\acer\\Anaconda3\\envs\\embvr\\lib\\site-packages\\IPython\\core\\interactiveshell.py\", line 2047, in showtraceback\n",
      "    value, tb, tb_offset=tb_offset)\n",
      "  File \"C:\\Users\\acer\\Anaconda3\\envs\\embvr\\lib\\site-packages\\IPython\\core\\ultratb.py\", line 1436, in structured_traceback\n",
      "    self, etype, value, tb, tb_offset, number_of_lines_of_context)\n",
      "  File \"C:\\Users\\acer\\Anaconda3\\envs\\embvr\\lib\\site-packages\\IPython\\core\\ultratb.py\", line 1336, in structured_traceback\n",
      "    self, etype, value, tb, tb_offset, number_of_lines_of_context\n",
      "  File \"C:\\Users\\acer\\Anaconda3\\envs\\embvr\\lib\\site-packages\\IPython\\core\\ultratb.py\", line 1211, in structured_traceback\n",
      "    chained_exceptions_tb_offset)\n",
      "  File \"C:\\Users\\acer\\Anaconda3\\envs\\embvr\\lib\\site-packages\\IPython\\core\\ultratb.py\", line 1150, in format_exception_as_a_whole\n",
      "    last_unique, recursion_repeat = find_recursion(orig_etype, evalue, records)\n",
      "  File \"C:\\Users\\acer\\Anaconda3\\envs\\embvr\\lib\\site-packages\\IPython\\core\\ultratb.py\", line 451, in find_recursion\n",
      "    return len(records), 0\n",
      "TypeError: object of type 'NoneType' has no len()\n",
      "\n",
      "During handling of the above exception, another exception occurred:\n",
      "\n",
      "Traceback (most recent call last):\n",
      "  File \"C:\\Users\\acer\\Anaconda3\\envs\\embvr\\lib\\site-packages\\IPython\\core\\interactiveshell.py\", line 2044, in showtraceback\n",
      "    stb = value._render_traceback_()\n",
      "AttributeError: 'TypeError' object has no attribute '_render_traceback_'\n",
      "\n",
      "During handling of the above exception, another exception occurred:\n",
      "\n",
      "Traceback (most recent call last):\n",
      "  File \"C:\\Users\\acer\\Anaconda3\\envs\\embvr\\lib\\site-packages\\IPython\\core\\ultratb.py\", line 1169, in get_records\n",
      "    return _fixed_getinnerframes(etb, number_of_lines_of_context, tb_offset)\n",
      "  File \"C:\\Users\\acer\\Anaconda3\\envs\\embvr\\lib\\site-packages\\IPython\\core\\ultratb.py\", line 316, in wrapped\n",
      "    return f(*args, **kwargs)\n",
      "  File \"C:\\Users\\acer\\Anaconda3\\envs\\embvr\\lib\\site-packages\\IPython\\core\\ultratb.py\", line 350, in _fixed_getinnerframes\n",
      "    records = fix_frame_records_filenames(inspect.getinnerframes(etb, context))\n",
      "  File \"C:\\Users\\acer\\Anaconda3\\envs\\embvr\\lib\\inspect.py\", line 1500, in getinnerframes\n",
      "    frameinfo = (tb.tb_frame,) + getframeinfo(tb, context)\n",
      "  File \"C:\\Users\\acer\\Anaconda3\\envs\\embvr\\lib\\inspect.py\", line 1458, in getframeinfo\n",
      "    filename = getsourcefile(frame) or getfile(frame)\n",
      "  File \"C:\\Users\\acer\\Anaconda3\\envs\\embvr\\lib\\inspect.py\", line 696, in getsourcefile\n",
      "    if getattr(getmodule(object, filename), '__loader__', None) is not None:\n",
      "  File \"C:\\Users\\acer\\Anaconda3\\envs\\embvr\\lib\\inspect.py\", line 733, in getmodule\n",
      "    if ismodule(module) and hasattr(module, '__file__'):\n",
      "  File \"C:\\Users\\acer\\Anaconda3\\envs\\embvr\\lib\\site-packages\\tensorflow\\__init__.py\", line 50, in __getattr__\n",
      "    module = self._load()\n",
      "  File \"C:\\Users\\acer\\Anaconda3\\envs\\embvr\\lib\\site-packages\\tensorflow\\__init__.py\", line 44, in _load\n",
      "    module = _importlib.import_module(self.__name__)\n",
      "  File \"C:\\Users\\acer\\Anaconda3\\envs\\embvr\\lib\\importlib\\__init__.py\", line 127, in import_module\n",
      "    return _bootstrap._gcd_import(name[level:], package, level)\n",
      "  File \"<frozen importlib._bootstrap>\", line 1006, in _gcd_import\n",
      "  File \"<frozen importlib._bootstrap>\", line 983, in _find_and_load\n",
      "  File \"<frozen importlib._bootstrap>\", line 965, in _find_and_load_unlocked\n",
      "ModuleNotFoundError: No module named 'tensorflow_core.estimator'\n"
     ]
    }
   ],
   "source": [
    "vid_capture = cv2.VideoCapture(0)\n",
    "faceCascade = cv2.CascadeClassifier(path)\n",
    "\n",
    "while True:\n",
    "    \n",
    "    ret, frames = vid_capture.read()\n",
    "    if vid_capture.isOpened(): \n",
    "        width  = vid_capture.get(3)  # float `width`\n",
    "        height = vid_capture.get(4)  # float `height`\n",
    "\n",
    "    gray = cv2.cvtColor(frames, cv2.COLOR_BGR2GRAY)\n",
    "    \n",
    "    # Here we set the minimum size for the opencv window to detect faces\n",
    "    faces = faceCascade.detectMultiScale(gray, \n",
    "                                         scaleFactor = 1.1, \n",
    "                                         minNeighbors = 6, \n",
    "                                         minSize = (int(0.1*height), int(0.1*width)), \n",
    "                                         flags = cv2.CASCADE_SCALE_IMAGE)\n",
    "    \n",
    "    for (x, y, w, h) in faces: \n",
    "        cv2.rectangle(frames, (x, y), (x+w, y+h), (0, 0, 255), 2)\n",
    "        \n",
    "    cv2.imshow('Video', frames)\n",
    "    \n",
    "    if cv2.waitKey(1) & 0xFF == ord(\"q\"): \n",
    "        break\n",
    "        \n",
    "cv2.destroyAllWindows()"
   ]
  },
  {
   "cell_type": "code",
   "execution_count": null,
   "metadata": {},
   "outputs": [],
   "source": []
  },
  {
   "cell_type": "code",
   "execution_count": 6,
   "metadata": {},
   "outputs": [],
   "source": [
    "import os; \n"
   ]
  },
  {
   "cell_type": "code",
   "execution_count": null,
   "metadata": {},
   "outputs": [
    {
     "name": "stderr",
     "output_type": "stream",
     "text": [
      "ERROR:root:Internal Python error in the inspect module.\n",
      "Below is the traceback from this internal error.\n",
      "\n",
      "ERROR:root:Internal Python error in the inspect module.\n",
      "Below is the traceback from this internal error.\n",
      "\n",
      "ERROR:root:Internal Python error in the inspect module.\n",
      "Below is the traceback from this internal error.\n",
      "\n"
     ]
    },
    {
     "name": "stdout",
     "output_type": "stream",
     "text": [
      "Traceback (most recent call last):\n",
      "  File \"C:\\Users\\acer\\Anaconda3\\envs\\embvr\\lib\\site-packages\\IPython\\core\\interactiveshell.py\", line 3417, in run_code\n",
      "    exec(code_obj, self.user_global_ns, self.user_ns)\n",
      "  File \"<ipython-input-4-57f7effab783>\", line 2, in <module>\n",
      "    os.makedir(\"./Imgs\")\n",
      "AttributeError: module 'os' has no attribute 'makedir'\n",
      "\n",
      "During handling of the above exception, another exception occurred:\n",
      "\n",
      "Traceback (most recent call last):\n",
      "  File \"C:\\Users\\acer\\Anaconda3\\envs\\embvr\\lib\\site-packages\\IPython\\core\\interactiveshell.py\", line 2044, in showtraceback\n",
      "    stb = value._render_traceback_()\n",
      "AttributeError: 'AttributeError' object has no attribute '_render_traceback_'\n",
      "\n",
      "During handling of the above exception, another exception occurred:\n",
      "\n",
      "Traceback (most recent call last):\n",
      "  File \"C:\\Users\\acer\\Anaconda3\\envs\\embvr\\lib\\site-packages\\IPython\\core\\ultratb.py\", line 1169, in get_records\n",
      "    return _fixed_getinnerframes(etb, number_of_lines_of_context, tb_offset)\n",
      "  File \"C:\\Users\\acer\\Anaconda3\\envs\\embvr\\lib\\site-packages\\IPython\\core\\ultratb.py\", line 316, in wrapped\n",
      "    return f(*args, **kwargs)\n",
      "  File \"C:\\Users\\acer\\Anaconda3\\envs\\embvr\\lib\\site-packages\\IPython\\core\\ultratb.py\", line 350, in _fixed_getinnerframes\n",
      "    records = fix_frame_records_filenames(inspect.getinnerframes(etb, context))\n",
      "  File \"C:\\Users\\acer\\Anaconda3\\envs\\embvr\\lib\\inspect.py\", line 1500, in getinnerframes\n",
      "    frameinfo = (tb.tb_frame,) + getframeinfo(tb, context)\n",
      "  File \"C:\\Users\\acer\\Anaconda3\\envs\\embvr\\lib\\inspect.py\", line 1458, in getframeinfo\n",
      "    filename = getsourcefile(frame) or getfile(frame)\n",
      "  File \"C:\\Users\\acer\\Anaconda3\\envs\\embvr\\lib\\inspect.py\", line 696, in getsourcefile\n",
      "    if getattr(getmodule(object, filename), '__loader__', None) is not None:\n",
      "  File \"C:\\Users\\acer\\Anaconda3\\envs\\embvr\\lib\\inspect.py\", line 733, in getmodule\n",
      "    if ismodule(module) and hasattr(module, '__file__'):\n",
      "  File \"C:\\Users\\acer\\Anaconda3\\envs\\embvr\\lib\\site-packages\\tensorflow\\__init__.py\", line 50, in __getattr__\n",
      "    module = self._load()\n",
      "  File \"C:\\Users\\acer\\Anaconda3\\envs\\embvr\\lib\\site-packages\\tensorflow\\__init__.py\", line 44, in _load\n",
      "    module = _importlib.import_module(self.__name__)\n",
      "  File \"C:\\Users\\acer\\Anaconda3\\envs\\embvr\\lib\\importlib\\__init__.py\", line 127, in import_module\n",
      "    return _bootstrap._gcd_import(name[level:], package, level)\n",
      "  File \"<frozen importlib._bootstrap>\", line 1006, in _gcd_import\n",
      "  File \"<frozen importlib._bootstrap>\", line 983, in _find_and_load\n",
      "  File \"<frozen importlib._bootstrap>\", line 965, in _find_and_load_unlocked\n",
      "ModuleNotFoundError: No module named 'tensorflow_core.estimator'\n",
      "ERROR! Session/line number was not unique in database. History logging moved to new session 2305\n",
      "Traceback (most recent call last):\n",
      "  File \"C:\\Users\\acer\\Anaconda3\\envs\\embvr\\lib\\site-packages\\IPython\\core\\interactiveshell.py\", line 3417, in run_code\n",
      "    exec(code_obj, self.user_global_ns, self.user_ns)\n",
      "  File \"<ipython-input-4-57f7effab783>\", line 2, in <module>\n",
      "    os.makedir(\"./Imgs\")\n",
      "AttributeError: module 'os' has no attribute 'makedir'\n",
      "\n",
      "During handling of the above exception, another exception occurred:\n",
      "\n",
      "Traceback (most recent call last):\n",
      "  File \"C:\\Users\\acer\\Anaconda3\\envs\\embvr\\lib\\site-packages\\IPython\\core\\interactiveshell.py\", line 2044, in showtraceback\n",
      "    stb = value._render_traceback_()\n",
      "AttributeError: 'AttributeError' object has no attribute '_render_traceback_'\n",
      "\n",
      "During handling of the above exception, another exception occurred:\n",
      "\n",
      "Traceback (most recent call last):\n",
      "  File \"C:\\Users\\acer\\Anaconda3\\envs\\embvr\\lib\\site-packages\\IPython\\core\\interactiveshell.py\", line 3337, in run_ast_nodes\n",
      "    if (await self.run_code(code, result,  async_=asy)):\n",
      "  File \"C:\\Users\\acer\\Anaconda3\\envs\\embvr\\lib\\site-packages\\IPython\\core\\interactiveshell.py\", line 3434, in run_code\n",
      "    self.showtraceback(running_compiled_code=True)\n",
      "  File \"C:\\Users\\acer\\Anaconda3\\envs\\embvr\\lib\\site-packages\\IPython\\core\\interactiveshell.py\", line 2047, in showtraceback\n",
      "    value, tb, tb_offset=tb_offset)\n",
      "  File \"C:\\Users\\acer\\Anaconda3\\envs\\embvr\\lib\\site-packages\\IPython\\core\\ultratb.py\", line 1436, in structured_traceback\n",
      "    self, etype, value, tb, tb_offset, number_of_lines_of_context)\n",
      "  File \"C:\\Users\\acer\\Anaconda3\\envs\\embvr\\lib\\site-packages\\IPython\\core\\ultratb.py\", line 1336, in structured_traceback\n",
      "    self, etype, value, tb, tb_offset, number_of_lines_of_context\n",
      "  File \"C:\\Users\\acer\\Anaconda3\\envs\\embvr\\lib\\site-packages\\IPython\\core\\ultratb.py\", line 1193, in structured_traceback\n",
      "    tb_offset)\n",
      "  File \"C:\\Users\\acer\\Anaconda3\\envs\\embvr\\lib\\site-packages\\IPython\\core\\ultratb.py\", line 1150, in format_exception_as_a_whole\n",
      "    last_unique, recursion_repeat = find_recursion(orig_etype, evalue, records)\n",
      "  File \"C:\\Users\\acer\\Anaconda3\\envs\\embvr\\lib\\site-packages\\IPython\\core\\ultratb.py\", line 451, in find_recursion\n",
      "    return len(records), 0\n",
      "TypeError: object of type 'NoneType' has no len()\n",
      "\n",
      "During handling of the above exception, another exception occurred:\n",
      "\n",
      "Traceback (most recent call last):\n",
      "  File \"C:\\Users\\acer\\Anaconda3\\envs\\embvr\\lib\\site-packages\\IPython\\core\\interactiveshell.py\", line 2044, in showtraceback\n",
      "    stb = value._render_traceback_()\n",
      "AttributeError: 'TypeError' object has no attribute '_render_traceback_'\n",
      "\n",
      "During handling of the above exception, another exception occurred:\n",
      "\n",
      "Traceback (most recent call last):\n",
      "  File \"C:\\Users\\acer\\Anaconda3\\envs\\embvr\\lib\\site-packages\\IPython\\core\\ultratb.py\", line 1169, in get_records\n",
      "    return _fixed_getinnerframes(etb, number_of_lines_of_context, tb_offset)\n",
      "  File \"C:\\Users\\acer\\Anaconda3\\envs\\embvr\\lib\\site-packages\\IPython\\core\\ultratb.py\", line 316, in wrapped\n",
      "    return f(*args, **kwargs)\n",
      "  File \"C:\\Users\\acer\\Anaconda3\\envs\\embvr\\lib\\site-packages\\IPython\\core\\ultratb.py\", line 350, in _fixed_getinnerframes\n",
      "    records = fix_frame_records_filenames(inspect.getinnerframes(etb, context))\n",
      "  File \"C:\\Users\\acer\\Anaconda3\\envs\\embvr\\lib\\inspect.py\", line 1500, in getinnerframes\n",
      "    frameinfo = (tb.tb_frame,) + getframeinfo(tb, context)\n",
      "  File \"C:\\Users\\acer\\Anaconda3\\envs\\embvr\\lib\\inspect.py\", line 1458, in getframeinfo\n",
      "    filename = getsourcefile(frame) or getfile(frame)\n",
      "  File \"C:\\Users\\acer\\Anaconda3\\envs\\embvr\\lib\\inspect.py\", line 696, in getsourcefile\n",
      "    if getattr(getmodule(object, filename), '__loader__', None) is not None:\n",
      "  File \"C:\\Users\\acer\\Anaconda3\\envs\\embvr\\lib\\inspect.py\", line 733, in getmodule\n",
      "    if ismodule(module) and hasattr(module, '__file__'):\n",
      "  File \"C:\\Users\\acer\\Anaconda3\\envs\\embvr\\lib\\site-packages\\tensorflow\\__init__.py\", line 50, in __getattr__\n",
      "    module = self._load()\n",
      "  File \"C:\\Users\\acer\\Anaconda3\\envs\\embvr\\lib\\site-packages\\tensorflow\\__init__.py\", line 44, in _load\n",
      "    module = _importlib.import_module(self.__name__)\n",
      "  File \"C:\\Users\\acer\\Anaconda3\\envs\\embvr\\lib\\importlib\\__init__.py\", line 127, in import_module\n",
      "    return _bootstrap._gcd_import(name[level:], package, level)\n",
      "  File \"<frozen importlib._bootstrap>\", line 1006, in _gcd_import\n",
      "  File \"<frozen importlib._bootstrap>\", line 983, in _find_and_load\n",
      "  File \"<frozen importlib._bootstrap>\", line 965, in _find_and_load_unlocked\n",
      "ModuleNotFoundError: No module named 'tensorflow_core.estimator'\n",
      "Traceback (most recent call last):\n",
      "  File \"C:\\Users\\acer\\Anaconda3\\envs\\embvr\\lib\\site-packages\\IPython\\core\\interactiveshell.py\", line 3417, in run_code\n",
      "    exec(code_obj, self.user_global_ns, self.user_ns)\n",
      "  File \"<ipython-input-4-57f7effab783>\", line 2, in <module>\n",
      "    os.makedir(\"./Imgs\")\n",
      "AttributeError: module 'os' has no attribute 'makedir'\n",
      "\n",
      "During handling of the above exception, another exception occurred:\n",
      "\n",
      "Traceback (most recent call last):\n",
      "  File \"C:\\Users\\acer\\Anaconda3\\envs\\embvr\\lib\\site-packages\\IPython\\core\\interactiveshell.py\", line 2044, in showtraceback\n",
      "    stb = value._render_traceback_()\n",
      "AttributeError: 'AttributeError' object has no attribute '_render_traceback_'\n",
      "\n",
      "During handling of the above exception, another exception occurred:\n",
      "\n",
      "Traceback (most recent call last):\n",
      "  File \"C:\\Users\\acer\\Anaconda3\\envs\\embvr\\lib\\site-packages\\IPython\\core\\interactiveshell.py\", line 3337, in run_ast_nodes\n",
      "    if (await self.run_code(code, result,  async_=asy)):\n",
      "  File \"C:\\Users\\acer\\Anaconda3\\envs\\embvr\\lib\\site-packages\\IPython\\core\\interactiveshell.py\", line 3434, in run_code\n",
      "    self.showtraceback(running_compiled_code=True)\n",
      "  File \"C:\\Users\\acer\\Anaconda3\\envs\\embvr\\lib\\site-packages\\IPython\\core\\interactiveshell.py\", line 2047, in showtraceback\n",
      "    value, tb, tb_offset=tb_offset)\n",
      "  File \"C:\\Users\\acer\\Anaconda3\\envs\\embvr\\lib\\site-packages\\IPython\\core\\ultratb.py\", line 1436, in structured_traceback\n",
      "    self, etype, value, tb, tb_offset, number_of_lines_of_context)\n",
      "  File \"C:\\Users\\acer\\Anaconda3\\envs\\embvr\\lib\\site-packages\\IPython\\core\\ultratb.py\", line 1336, in structured_traceback\n",
      "    self, etype, value, tb, tb_offset, number_of_lines_of_context\n",
      "  File \"C:\\Users\\acer\\Anaconda3\\envs\\embvr\\lib\\site-packages\\IPython\\core\\ultratb.py\", line 1193, in structured_traceback\n",
      "    tb_offset)\n",
      "  File \"C:\\Users\\acer\\Anaconda3\\envs\\embvr\\lib\\site-packages\\IPython\\core\\ultratb.py\", line 1150, in format_exception_as_a_whole\n",
      "    last_unique, recursion_repeat = find_recursion(orig_etype, evalue, records)\n",
      "  File \"C:\\Users\\acer\\Anaconda3\\envs\\embvr\\lib\\site-packages\\IPython\\core\\ultratb.py\", line 451, in find_recursion\n",
      "    return len(records), 0\n",
      "TypeError: object of type 'NoneType' has no len()\n",
      "\n",
      "During handling of the above exception, another exception occurred:\n",
      "\n",
      "Traceback (most recent call last):\n",
      "  File \"C:\\Users\\acer\\Anaconda3\\envs\\embvr\\lib\\site-packages\\IPython\\core\\interactiveshell.py\", line 2044, in showtraceback\n",
      "    stb = value._render_traceback_()\n",
      "AttributeError: 'TypeError' object has no attribute '_render_traceback_'\n",
      "\n",
      "During handling of the above exception, another exception occurred:\n",
      "\n",
      "Traceback (most recent call last):\n",
      "  File \"C:\\Users\\acer\\Anaconda3\\envs\\embvr\\lib\\site-packages\\IPython\\core\\interactiveshell.py\", line 2922, in _run_cell\n",
      "    return runner(coro)\n",
      "  File \"C:\\Users\\acer\\Anaconda3\\envs\\embvr\\lib\\site-packages\\IPython\\core\\async_helpers.py\", line 68, in _pseudo_sync_runner\n",
      "    coro.send(None)\n",
      "  File \"C:\\Users\\acer\\Anaconda3\\envs\\embvr\\lib\\site-packages\\IPython\\core\\interactiveshell.py\", line 3146, in run_cell_async\n",
      "    interactivity=interactivity, compiler=compiler, result=result)\n",
      "  File \"C:\\Users\\acer\\Anaconda3\\envs\\embvr\\lib\\site-packages\\IPython\\core\\interactiveshell.py\", line 3356, in run_ast_nodes\n",
      "    self.showtraceback()\n",
      "  File \"C:\\Users\\acer\\Anaconda3\\envs\\embvr\\lib\\site-packages\\IPython\\core\\interactiveshell.py\", line 2047, in showtraceback\n",
      "    value, tb, tb_offset=tb_offset)\n",
      "  File \"C:\\Users\\acer\\Anaconda3\\envs\\embvr\\lib\\site-packages\\IPython\\core\\ultratb.py\", line 1436, in structured_traceback\n",
      "    self, etype, value, tb, tb_offset, number_of_lines_of_context)\n",
      "  File \"C:\\Users\\acer\\Anaconda3\\envs\\embvr\\lib\\site-packages\\IPython\\core\\ultratb.py\", line 1336, in structured_traceback\n",
      "    self, etype, value, tb, tb_offset, number_of_lines_of_context\n",
      "  File \"C:\\Users\\acer\\Anaconda3\\envs\\embvr\\lib\\site-packages\\IPython\\core\\ultratb.py\", line 1211, in structured_traceback\n",
      "    chained_exceptions_tb_offset)\n",
      "  File \"C:\\Users\\acer\\Anaconda3\\envs\\embvr\\lib\\site-packages\\IPython\\core\\ultratb.py\", line 1150, in format_exception_as_a_whole\n",
      "    last_unique, recursion_repeat = find_recursion(orig_etype, evalue, records)\n",
      "  File \"C:\\Users\\acer\\Anaconda3\\envs\\embvr\\lib\\site-packages\\IPython\\core\\ultratb.py\", line 451, in find_recursion\n",
      "    return len(records), 0\n",
      "TypeError: object of type 'NoneType' has no len()\n",
      "\n",
      "During handling of the above exception, another exception occurred:\n",
      "\n",
      "Traceback (most recent call last):\n",
      "  File \"C:\\Users\\acer\\Anaconda3\\envs\\embvr\\lib\\site-packages\\IPython\\core\\interactiveshell.py\", line 2044, in showtraceback\n",
      "    stb = value._render_traceback_()\n",
      "AttributeError: 'TypeError' object has no attribute '_render_traceback_'\n",
      "\n",
      "During handling of the above exception, another exception occurred:\n",
      "\n",
      "Traceback (most recent call last):\n",
      "  File \"C:\\Users\\acer\\Anaconda3\\envs\\embvr\\lib\\site-packages\\IPython\\core\\ultratb.py\", line 1169, in get_records\n",
      "    return _fixed_getinnerframes(etb, number_of_lines_of_context, tb_offset)\n",
      "  File \"C:\\Users\\acer\\Anaconda3\\envs\\embvr\\lib\\site-packages\\IPython\\core\\ultratb.py\", line 316, in wrapped\n",
      "    return f(*args, **kwargs)\n",
      "  File \"C:\\Users\\acer\\Anaconda3\\envs\\embvr\\lib\\site-packages\\IPython\\core\\ultratb.py\", line 350, in _fixed_getinnerframes\n",
      "    records = fix_frame_records_filenames(inspect.getinnerframes(etb, context))\n",
      "  File \"C:\\Users\\acer\\Anaconda3\\envs\\embvr\\lib\\inspect.py\", line 1500, in getinnerframes\n",
      "    frameinfo = (tb.tb_frame,) + getframeinfo(tb, context)\n",
      "  File \"C:\\Users\\acer\\Anaconda3\\envs\\embvr\\lib\\inspect.py\", line 1458, in getframeinfo\n",
      "    filename = getsourcefile(frame) or getfile(frame)\n",
      "  File \"C:\\Users\\acer\\Anaconda3\\envs\\embvr\\lib\\inspect.py\", line 696, in getsourcefile\n",
      "    if getattr(getmodule(object, filename), '__loader__', None) is not None:\n",
      "  File \"C:\\Users\\acer\\Anaconda3\\envs\\embvr\\lib\\inspect.py\", line 733, in getmodule\n",
      "    if ismodule(module) and hasattr(module, '__file__'):\n",
      "  File \"C:\\Users\\acer\\Anaconda3\\envs\\embvr\\lib\\site-packages\\tensorflow\\__init__.py\", line 50, in __getattr__\n",
      "    module = self._load()\n",
      "  File \"C:\\Users\\acer\\Anaconda3\\envs\\embvr\\lib\\site-packages\\tensorflow\\__init__.py\", line 44, in _load\n",
      "    module = _importlib.import_module(self.__name__)\n",
      "  File \"C:\\Users\\acer\\Anaconda3\\envs\\embvr\\lib\\importlib\\__init__.py\", line 127, in import_module\n",
      "    return _bootstrap._gcd_import(name[level:], package, level)\n",
      "  File \"<frozen importlib._bootstrap>\", line 1006, in _gcd_import\n",
      "  File \"<frozen importlib._bootstrap>\", line 983, in _find_and_load\n",
      "  File \"<frozen importlib._bootstrap>\", line 965, in _find_and_load_unlocked\n",
      "ModuleNotFoundError: No module named 'tensorflow_core.estimator'\n"
     ]
    }
   ],
   "source": [
    "import os\n",
    "os.makedir(\"./Imgs\")"
   ]
  },
  {
   "cell_type": "code",
   "execution_count": 7,
   "metadata": {},
   "outputs": [],
   "source": [
    "import cv2"
   ]
  },
  {
   "cell_type": "code",
   "execution_count": null,
   "metadata": {},
   "outputs": [],
   "source": []
  }
 ],
 "metadata": {
  "kernelspec": {
   "display_name": "computerVision",
   "language": "python",
   "name": "computervision"
  },
  "language_info": {
   "codemirror_mode": {
    "name": "ipython",
    "version": 3
   },
   "file_extension": ".py",
   "mimetype": "text/x-python",
   "name": "python",
   "nbconvert_exporter": "python",
   "pygments_lexer": "ipython3",
   "version": "3.7.1"
  }
 },
 "nbformat": 4,
 "nbformat_minor": 2
}
